Workbook

Sheet Anleitung
A1: NK-Abrechnung Teinacher Str. 4 – Excel-Version
A3: Zweck
A4: Diese Mappe rechnet die Nebenkostenabrechnung wie die App – ohne Programm. Zählerstände und Kosten eintragen, alle Ergebnisse berechnen sich sofort selbst.
A6: Farblegende
A7: Gelbes Feld, blaue Schrift = hier eintragen/ändern.
A8: Schwarze Schrift = Formel, nicht überschreiben. Grüne Schrift = Verweis auf ein anderes Blatt.
A10: Blätter
A11: Übersicht – Ergebnisse je Partei und Vergleich mit den dokumentierten Werten (Kontrolle).
A12: Zählerstände – Ablesedatum und Zählerstand je Stichtag (Stand 4 = Folgeperiode, noch leer).
A13: Kosten – Strompreis, Grundpreis, Wasser-/Niederschlagstarife, Versicherung, Grundsteuer.
A14: Perioden – Parteien, Zeiträume, Vorauszahlungen, welche Stichtage gelten.
A15: Berechnung – Verbrauch, Heizschlüssel, COP-Plausibilitätsprüfung.
... A31: Zählerstände Beltz-Periode: 40467,30 kWh (WP-Strom, Stichtag 3) – Dezimalkomma wie in Deutschland üblich.

Sheet Übersicht
A1: Übersicht der Ergebnisse
A2: Vergleich mit den dokumentierten Werten aus der Projekt-Zusammenfassung (19.06.2026, vom Nutzer). Weichen die Werte ab, wurden Eingaben geändert.
A4: Partei | B4: SOLL | C4: IST | D4: Saldo | E4: Dokumentierter SOLL-Wert | F4: Abweichung | G4: Prüfung
A5: Felix Adameck (P1) | B5: =Abr_P1_Felix!C22 -> 3262.67 | C5: =Abr_P1_Felix!C23 -> 2545 | D5: =Abr_P1_Felix!C24 -> 717.67 | E5: 3262.66 | F5: =B5-E5 -> 0.01 | G5: =IF(ABS(F5)<=0.02,"stimmt überein","weicht ab") -> stimmt überein
A6: Leerstand (Thomas Weis) | B6: =Abr_Leerstand!C17 -> 706.81 | C6: 0 | D6: =Abr_Leerstand!C17 -> 706.81 | E6: 706.81 | F6: =B6-E6 -> 0 | G6: =IF(ABS(F6)<=0.02,"stimmt überein","weicht ab") -> stimmt überein
A7: Fam. Beltz (P2) | B7: =Abr_P2_Beltz!C21 -> 3110.31 | C7: =Abr_P2_Beltz!C22 -> 2585 | D7: =Abr_P2_Beltz!C23 -> 525.31 | E7: 3110.31 | F7: =B7-E7 -> 0 | G7: =IF(ABS(F7)<=0.02,"stimmt überein","weicht ab") -> stimmt überein
A8: WW-EG Kulanz (erlassen) | B8: =Eigentümer!B30 -> 584.27 | E8: 584.27 | F8: =B8-E8 -> 0 | G8: =IF(ABS(F8)<=0.02,"stimmt überein","weicht ab") -> stimmt überein
A9: Folgeperiode (ab Eigentümerwechsel) | B9: =Abr_Folgeperiode!C28 | C9: =Abr_Folgeperiode!C29 -> 0 | D9: =Abr_Folgeperiode!C30 -> Stand 4 fehlt | G9: noch keine Vergleichswerte
A11: Toleranz 2 Cent (Rundungsunterschiede im Ausgangsdokument, z. B. Grundsteuer 235,97 vs. 235,98 €).
A12: Positiver Saldo = Nachzahlung des Mieters bzw. von Thomas zu tragen.
A14: Heizschlüssel & COP | B14: Heizschlüssel UG | C14: COP | D14: Prüfung
A15: Periode 1 (Feb 2024 – Mai 2025) | B15: =Berechnung!I6 -> 0.46595461 | C15: =Berechnung!J6 -> 3.297578 | D15: =Berechnung!K6 -> plausibel
A16: Leerstand + Periode 2 (Mai 2025 – Jun 2026) | B16: =Berechnung!I8 -> 0.68888328 | C16: =Berechnung!J8 -> 2.0838156 | D16: =Berechnung!K8 -> plausibel

Sheet Zählerstände
A1: Zählerstände (Eingabe)
A2: Gelbe Felder mit blauer Schrift sind Eingabefelder. Datum der Ablesung und Zählerstand eintragen – alles andere rechnet die Mappe selbst.
E3: Stichtag 1 (Start Periode 1) | F3: Stichtag 2 (Ende P1 / Start Leerstand) | G3: Stichtag 3 (Abrechnung Beltz) | H3: Stichtag 4 (Folgeperiode, noch offen)
A4: Datum der Ablesung | E4: 45323 | F4: 45778 | G4: 46192
A5: Kürzel | B5: Zähler | C5: Zähler-Nr. | D5: Einheit | E5: Stand 1 | F5: Stand 2 | G5: Stand 3 | H5: Stand 4 | I5: Hinweis
A6: WP | B6: WP-Strom (Wärmepumpe) | C6: 401746-0222 | D6: kWh | E6: 17705.44 | F6: 29062.26 | G6: 40467.3
A7: UV | B7: Haushaltsstrom UG | C7: 401349-0222 | D7: kWh | E7: 3396.16 | F7: 5480.9 | G7: 7599.68
A8: WMZ_UG | B8: Wärmemengenzähler UG | C8: 12654509 | D8: MWh | E8: 32.5 | F8: 49.95 | G8: 66.322 | I8: März-2026-Stand bewusst NICHT verwendet (falsches Register, COP unplausibel)
A9: WMZ_EG | B9: Wärmemengenzähler EG+DG | C9: 12654523 | D9: MWh | E9: 33 | F9: 53 | G9: 60.394
A10: KW_UG | B10: Kaltwasser UG | C10: 12050176 | D10: m³ | E10: 61.904 | F10: 107.81 | G10: 149.138
A11: WW_UG | B11: Warmwasser UG | C11: 20424827 | D11: m³ | E11: 35.021 | F11: 53.07 | G11: 63.495
A12: WW_EG | B12: Warmwasser EG (Kulanz Christine) | C12: 21415602 | D12: m³ | E12: 6.569 | G12: 120.116 | I12: Stand 2 nicht nötig (Kulanz rechnet Stand 1 bis 3)
A14: Die Werte in Stand 1–3 stammen aus der Projekt-Zusammenfassung vom 19.06.2026 (vom Nutzer geliefert). Stand 4 ist für die Folgeperiode nach dem Eigentümerwechsel gedacht.

Sheet Kosten
A1: Kostensätze (Eingabe)
A3: Parameter | B3: Wert | C3: Einheit | D3: Hinweis / Quelle
A4: Strompreis (EnBW) | B4: 0.2462 | C4: €/kWh | D4: Projekt-Zusammenfassung 19.06.2026
A5: Fläche UG | B5: 88 | C5: m²
A6: Gesamtfläche | B6: 270 | C6: m² | D6: UG 88 + EG 182
A7: UG-Anteil | B7: =B5/B6 -> 0.32592593 | D7: Fläche UG / Gesamtfläche
A8: EnBW-Grundpreis Periode 1 (15 Monate, Haus gesamt) | B8: 563.11 | C8: €
A9: EnBW-Grundpreis Periode 2 (Haus gesamt) | B9: 375.41 | C9: € | D9: Basis für Monatssatz; finale EnBW-Jahresrechnung 2025/26 noch prüfen
A10: … Anzahl Monate dieser Rechnung | B10: 8 | C10: Monate
A11: EnBW-Grundpreis pro Monat | B11: =B9/B10 -> 46.92625 | C11: €/Monat
A12: Warmwasser-Heizenergie (Gerätekennwert) | B12: 20.9 | C12: kWh/m³ | D12: Mitsubishi Gerätekennwert
A13: Warmwasser-Heizenergie in € | B13: =B12*B4 -> 5.14558 | C13: €/m³ | D13: kWh/m³ × Strompreis
A14: Gebäudeversicherung UG | B14: 24.18 | C14: €/Monat
A15: Grundsteuer B (UG-Anteil) | B15: 188.78 | C15: €/Jahr
A16: Grundsteuer B pro Monat | B16: =B15/12 -> 15.731667 | C16: €/Monat
A17: Versiegelte Fläche Niederschlagswasser | B17: 226 | C17: m²
A18: Renovierungspauschale Beltz (vereinbart) | B18: 80 | C18: €
A19: Tarife je Kalenderjahr
A20: Jahr | B20: Wassertarif inkl. Abwasser (€/m³) | C20: Niederschlag-Gebühr (€/m²) | D20: Niederschlag UG pro Monat (€) | E20: Hinweis
A21: 2024 | B21: 7.63 | C21: 0.99 | D21: =ROUND($B$17*C21/12*$B$7,2) -> 6.08
A22: 2025 | B22: 7.44 | C22: 0.81 | D22: =ROUND($B$17*C22/12*$B$7,2) -> 4.97
A23: 2026 | B23: 7.44 | C23: 0.81 | D23: =ROUND($B$17*C23/12*$B$7,2) -> 4.97 | E23: Fortschreibung 2025 – bei neuem Bescheid ändern
A24: 2027 | B24: 7.44 | C24: 0.81 | D24: =ROUND($B$17*C24/12*$B$7,2) -> 4.97 | E24: Fortschreibung – bei neuem Bescheid ändern
A25: 2028 | B25: 7.44 | C25: 0.81 | D25: =ROUND($B$17*C25/12*$B$7,2) -> 4.97 | E25: Fortschreibung
A26: 2029 | B26: 7.44 | C26: 0.81 | D26: =ROUND($B$17*C26/12*$B$7,2) -> 4.97 | E26: Fortschreibung
A27: 2030 | B27: 7.44 | C27: 0.81 | D27: =ROUND($B$17*C27/12*$B$7,2) -> 4.97 | E27: Fortschreibung
A29: Niederschlag pro Monat wird auf Cent gerundet, wie in der App.

Sheet Perioden
A1: Perioden / Parteien (Eingabe)
A2: Stichtag-Nr. verweist auf die Spalten Stand 1–4 in 'Zählerstände'. Leerstand und Beltz teilen sich die Zählerperiode Stichtag 2→3 (Anteil = Monate / Summe der Monate).
A5: Kürzel | B5: Mieter / Partei | C5: Beginn | D5: Ende | E5: Monate | F5: Vorauszahlung €/Monat | G5: IST geleistet € | H5: Stichtag von (Nr.) | I5: Stichtag bis (Nr.) | J5: Anteil an Zählerperiode | K5: EnBW-Grundpreis Haus € | L5: Zähler von (Datum) | M5: Zähler bis (Datum)
A6: P1 | B6: Felix Adameck | C6: 45323 | D6: 45777 | E6: 15 | F6: 195 | G6: 2545 | H6: 1 | I6: 2 | J6: 1 | K6: =Kosten!B8 -> 563.11 | L6: =INDEX(Zählerstände!$E$4:$H$4,H6) -> 45323 | M6: =INDEX(Zählerstände!$E$4:$H$4,I6) -> 45778
A7: LEER | B7: Leerstand (Thomas Weis) | C7: 45778 | D7: 45869 | E7: 3 | F7: 0 | G7: 0 | H7: 2 | I7: 3 | J7: =E7/(E7+E8) -> 0.21428571 | K7: =Kosten!B11*E7 -> 140.77875 | L7: =INDEX(Zählerstände!$E$4:$H$4,H7) -> 45778 | M7: =INDEX(Zählerstände!$E$4:$H$4,I7) -> 46192
A8: P2 | B8: Fam. Kristin & Maximilian Beltz | C8: 45870 | D8: 46192 | E8: 11 | F8: 235 | G8: =E8*F8 -> 2585 | H8: 2 | I8: 3 | J8: =E8/(E7+E8) -> 0.78571429 | K8: =Kosten!B11*E8 -> 516.18875 | L8: =INDEX(Zählerstände!$E$4:$H$4,H8) -> 45778 | M8: =INDEX(Zählerstände!$E$4:$H$4,I8) -> 46192
A9: P3 | B9: Neuer Eigentümer (Name folgt) – Folgeperiode | C9: 46193 | D9: 46387 | E9: 6 | F9: 0 | G9: 0 | H9: 3 | I9: 4 | J9: 1 | K9: =Kosten!B11*E9 -> 281.5575 | L9: =INDEX(Zählerstände!$E$4:$H$4,H9) -> 46192 | M9: =INDEX(Zählerstände!$E$4:$H$4,I9) -> 0
A11: Hinweise
A12: P1: IST 2.545 € = tatsächlich erhaltene Vorauszahlungen (nicht 15 × 195 €).
A13: P2 Ende 19.06.2026 = Stichtag der Abschlussabrechnung (~11 Monate).
A14: P3 ist eine Platzhalter-Zeile für die Folgeperiode nach dem Eigentümerwechsel – Beginn, Ende, Monate und Zahlungen anpassen; Stichtag 4 in 'Zählerstände' eintragen.
A15: Maximal 24 Monate pro Periode (Monatsraster).

Sheet Berechnung
A1: Verbrauch, Heizschlüssel und COP-Plausibilität
A2: Alles per Formel aus 'Zählerstände' und 'Perioden'. Leere Zellen = Zählerstand fehlt noch.
A5: Kürzel | B5: Partei | C5: Δ WP-Strom kWh | D5: Δ Haushaltsstrom kWh | E5: Δ WMZ UG MWh | F5: Δ WMZ EG MWh | G5: Δ Kaltwasser m³ | H5: Δ Warmwasser UG m³ | I5: Heizschlüssel UG | J5: COP | K5: COP-Prüfung
A6: =Perioden!A6 -> P1 | B6: =Perioden!B6 -> Felix Adameck | C6: =IF(COUNT(INDEX(Zählerstände!$E$6:$H$6,Perioden!$H6),INDEX(Zählerstände!$E$6:$H$6,Perioden!$I6))<2,"",INDEX(Zählerstände!$E$6:$H$6,Perioden!$I6)-INDEX(Zählerstände!$E$6:$H$6,Perioden!$H6)) -> 11356.82 | D6: =IF(COUNT(INDEX(Zählerstände!$E$7:$H$7,Perioden!$H6),INDEX(Zählerstände!$E$7:$H$7,Perioden!$I6))<2,"",INDEX(Zählerstände!$E$7:$H$7,Perioden!$I6)-INDEX(Zählerstände!$E$7:$H$7,Perioden!$H6)) -> 2084.74 | E6: =IF(COUNT(INDEX(Zählerstände!$E$8:$H$8,Perioden!$H6),INDEX(Zählerstände!$E$8:$H$8,Perioden!$I6))<2,"",INDEX(Zählerstände!$E$8:$H$8,Perioden!$I6)-INDEX(Zählerstände!$E$8:$H$8,Perioden!$H6)) -> 17.45 | F6: =IF(COUNT(INDEX(Zählerstände!$E$9:$H$9,Perioden!$H6),INDEX(Zählerstände!$E$9:$H$9,Perioden!$I6))<2,"",INDEX(Zählerstände!$E$9:$H$9,Perioden!$I6)-INDEX(Zählerstände!$E$9:$H$9,Perioden!$H6)) -> 20 | G6: =IF(COUNT(INDEX(Zählerstände!$E$10:$H$10,Perioden!$H6),INDEX(Zählerstände!$E$10:$H$10,Perioden!$I6))<2,"",INDEX(Zählerstände!$E$10:$H$10,Perioden!$I6)-INDEX(Zählerstände!$E$10:$H$10,Perioden!$H6)) -> 45.906 | H6: =IF(COUNT(INDEX(Zählerstände!$E$11:$H$11,Perioden!$H6),INDEX(Zählerstände!$E$11:$H$11,Perioden!$I6))<2,"",INDEX(Zählerstände!$E$11:$H$11,Perioden!$I6)-INDEX(Zählerstände!$E$11:$H$11,Perioden!$H6)) -> 18.049 | I6: =IF(OR(E6="",F6=""),"",E6/(E6+F6)) -> 0.46595461 | J6: =IF(OR(C6="",E6="",F6=""),"",(E6+F6)*1000/C6) -> 3.297578 | K6: =IF(J6="","",IF(AND(J6>=1.5,J6<=6),"plausibel","PRÜFEN")) -> plausibel
A7: =Perioden!A7 -> LEER | B7: =Perioden!B7 -> Leerstand (Thomas Weis) | C7: =IF(COUNT(INDEX(Zählerstände!$E$6:$H$6,Perioden!$H7),INDEX(Zählerstände!$E$6:$H$6,Perioden!$I7))<2,"",INDEX(Zählerstände!$E$6:$H$6,Perioden!$I7)-INDEX(Zählerstände!$E$6:$H$6,Perioden!$H7)) -> 11405.04 | D7: =IF(COUNT(INDEX(Zählerstände!$E$7:$H$7,Perioden!$H7),INDEX(Zählerstände!$E$7:$H$7,Perioden!$I7))<2,"",INDEX(Zählerstände!$E$7:$H$7,Perioden!$I7)-INDEX(Zählerstände!$E$7:$H$7,Perioden!$H7)) -> 2118.78 | E7: =IF(COUNT(INDEX(Zählerstände!$E$8:$H$8,Perioden!$H7),INDEX(Zählerstände!$E$8:$H$8,Perioden!$I7))<2,"",INDEX(Zählerstände!$E$8:$H$8,Perioden!$I7)-INDEX(Zählerstände!$E$8:$H$8,Perioden!$H7)) -> 16.372 | F7: =IF(COUNT(INDEX(Zählerstände!$E$9:$H$9,Perioden!$H7),INDEX(Zählerstände!$E$9:$H$9,Perioden!$I7))<2,"",INDEX(Zählerstände!$E$9:$H$9,Perioden!$I7)-INDEX(Zählerstände!$E$9:$H$9,Perioden!$H7)) -> 7.394 | G7: =IF(COUNT(INDEX(Zählerstände!$E$10:$H$10,Perioden!$H7),INDEX(Zählerstände!$E$10:$H$10,Perioden!$I7))<2,"",INDEX(Zählerstände!$E$10:$H$10,Perioden!$I7)-INDEX(Zählerstände!$E$10:$H$10,Perioden!$H7)) -> 41.328 | H7: =IF(COUNT(INDEX(Zählerstände!$E$11:$H$11,Perioden!$H7),INDEX(Zählerstände!$E$11:$H$11,Perioden!$I7))<2,"",INDEX(Zählerstände!$E$11:$H$11,Perioden!$I7)-INDEX(Zählerstände!$E$11:$H$11,Perioden!$H7)) -> 10.425 | I7: =IF(OR(E7="",F7=""),"",E7/(E7+F7)) -> 0.68888328 | J7: =IF(OR(C7="",E7="",F7=""),"",(E7+F7)*1000/C7) -> 2.0838156 | K7: =IF(J7="","",IF(AND(J7>=1.5,J7<=6),"plausibel","PRÜFEN")) -> plausibel
A8: =Perioden!A8 -> P2 | B8: =Perioden!B8 -> Fam. Kristin & Maximilian Beltz | C8: =IF(COUNT(INDEX(Zählerstände!$E$6:$H$6,Perioden!$H8),INDEX(Zählerstände!$E$6:$H$6,Perioden!$I8))<2,"",INDEX(Zählerstände!$E$6:$H$6,Perioden!$I8)-INDEX(Zählerstände!$E$6:$H$6,Perioden!$H8)) -> 11405.04 | D8: =IF(COUNT(INDEX(Zählerstände!$E$7:$H$7,Perioden!$H8),INDEX(Zählerstände!$E$7:$H$7,Perioden!$I8))<2,"",INDEX(Zählerstände!$E$7:$H$7,Perioden!$I8)-INDEX(Zählerstände!$E$7:$H$7,Perioden!$H8)) -> 2118.78 | E8: =IF(COUNT(INDEX(Zählerstände!$E$8:$H$8,Perioden!$H8),INDEX(Zählerstände!$E$8:$H$8,Perioden!$I8))<2,"",INDEX(Zählerstände!$E$8:$H$8,Perioden!$I8)-INDEX(Zählerstände!$E$8:$H$8,Perioden!$H8)) -> 16.372 | F8: =IF(COUNT(INDEX(Zählerstände!$E$9:$H$9,Perioden!$H8),INDEX(Zählerstände!$E$9:$H$9,Perioden!$I8))<2,"",INDEX(Zählerstände!$E$9:$H$9,Perioden!$I8)-INDEX(Zählerstände!$E$9:$H$9,Perioden!$H8)) -> 7.394 | G8: =IF(COUNT(INDEX(Zählerstände!$E$10:$H$10,Perioden!$H8),INDEX(Zählerstände!$E$10:$H$10,Perioden!$I8))<2,"",INDEX(Zählerstände!$E$10:$H$10,Perioden!$I8)-INDEX(Zählerstände!$E$10:$H$10,Perioden!$H8)) -> 41.328 | H8: =IF(COUNT(INDEX(Zählerstände!$E$11:$H$11,Perioden!$H8),INDEX(Zählerstände!$E$11:$H$11,Perioden!$I8))<2,"",INDEX(Zählerstände!$E$11:$H$11,Perioden!$I8)-INDEX(Zählerstände!$E$11:$H$11,Perioden!$H8)) -> 10.425 | I8: =IF(OR(E8="",F8=""),"",E8/(E8+F8)) -> 0.68888328 | J8: =IF(OR(C8="",E8="",F8=""),"",(E8+F8)*1000/C8) -> 2.0838156 | K8: =IF(J8="","",IF(AND(J8>=1.5,J8<=6),"plausibel","PRÜFEN")) -> plausibel
A9: =Perioden!A9 -> P3 | B9: =Perioden!B9 -> Neuer Eigentümer (Name folgt) – Folgeperiode | C9: =IF(COUNT(INDEX(Zählerstände!$E$6:$H$6,Perioden!$H9),INDEX(Zählerstände!$E$6:$H$6,Perioden!$I9))<2,"",INDEX(Zählerstände!$E$6:$H$6,Perioden!$I9)-INDEX(Zählerstände!$E$6:$H$6,Perioden!$H9)) | D9: =IF(COUNT(INDEX(Zählerstände!$E$7:$H$7,Perioden!$H9),INDEX(Zählerstände!$E$7:$H$7,Perioden!$I9))<2,"",INDEX(Zählerstände!$E$7:$H$7,Perioden!$I9)-INDEX(Zählerstände!$E$7:$H$7,Perioden!$H9)) | E9: =IF(COUNT(INDEX(Zählerstände!$E$8:$H$8,Perioden!$H9),INDEX(Zählerstände!$E$8:$H$8,Perioden!$I9))<2,"",INDEX(Zählerstände!$E$8:$H$8,Perioden!$I9)-INDEX(Zählerstände!$E$8:$H$8,Perioden!$H9)) | F9: =IF(COUNT(INDEX(Zählerstände!$E$9:$H$9,Perioden!$H9),INDEX(Zählerstände!$E$9:$H$9,Perioden!$I9))<2,"",INDEX(Zählerstände!$E$9:$H$9,Perioden!$I9)-INDEX(Zählerstände!$E$9:$H$9,Perioden!$H9)) | G9: =IF(COUNT(INDEX(Zählerstände!$E$10:$H$10,Perioden!$H9),INDEX(Zählerstände!$E$10:$H$10,Perioden!$I9))<2,"",INDEX(Zählerstände!$E$10:$H$10,Perioden!$I9)-INDEX(Zählerstände!$E$10:$H$10,Perioden!$H9)) | H9: =IF(COUNT(INDEX(Zählerstände!$E$11:$H$11,Perioden!$H9),INDEX(Zählerstände!$E$11:$H$11,Perioden!$I9))<2,"",INDEX(Zählerstände!$E$11:$H$11,Perioden!$I9)-INDEX(Zählerstände!$E$11:$H$11,Perioden!$H9)) | I9: =IF(OR(E9="",F9=""),"",E9/(E9+F9)) | J9: =IF(OR(C9="",E9="",F9=""),"",(E9+F9)*1000/C9) | K9: =IF(J9="","",IF(AND(J9>=1.5,J9<=6),"plausibel","PRÜFEN"))
A11: COP = erzeugte Wärme (WMZ UG + EG) / WP-Strom. Üblich: 2 bis 5. Ein Wert außerhalb 1,5–6 deutet auf einen Ablese- oder Registerfehler hin (Beispiel März 2026: COP 0,62 bzw. 7,94).

Sheet Abr_P1_Felix
A1: Nebenkostenabrechnung – Felix Adameck (Periode 1)
A2: Teinacher Str. 4, 75387 Neubulach
A4: Mieter / Partei | B4: =Perioden!B6 -> Felix Adameck
A5: Beginn | B5: =Perioden!C6 -> 45323
A6: Ende | B6: =Perioden!D6 -> 45777
A7: Monate | B7: =Perioden!E6 -> 15
A8: Heizschlüssel UG | B8: =Berechnung!I6 -> 0.46595461
A10: Position | B10: Berechnung | C10: Betrag
A11: Heizkosten Wärmepumpe | B11: WP-kWh × Anteil × Heizschlüssel × Strompreis | C11: =ROUND(Berechnung!C6*Perioden!J6*Berechnung!I6*Kosten!B4,2) -> 1302.83
A12: Warmwasser-Heizenergie | B12: Warmwasser-m³ × 20,9 kWh/m³ × Strompreis | C12: =ROUND(Berechnung!H6*Kosten!B13,2) -> 92.87
A13: Haushaltsstrom UV | B13: UV-kWh × Anteil × Strompreis | C13: =ROUND(Berechnung!D6*Perioden!J6*Kosten!B4,2) -> 513.26
A14: Stromgrundpreis (UG-Anteil) | B14: EnBW-Grundpreis P1 × UG-Anteil | C14: =ROUND(Perioden!K6*Kosten!B7,2) -> 183.53
A15: ="Wasser/Abwasser "&YEAR(Perioden!$C$6) -> Wasser/Abwasser 2024 | B15: (Kalt- + Warmwasser-m³ ÷ Monate) × Summe Monatstarife des Jahres | C15: =ROUND((Berechnung!G6+Berechnung!H6)/Perioden!E6*SUMIFS(Monatsraster!$E$5:$E$100,Monatsraster!$A$5:$A$100,Perioden!$A$6,Monatsraster!$D$5:$D$100,YEAR(Perioden!$C$6)),2) -> 357.85
A16: ="Wasser/Abwasser "&(YEAR(Perioden!$C$6)+1) -> Wasser/Abwasser 2025 | B16: wie oben, Folgejahr | C16: =ROUND((Berechnung!G6+Berechnung!H6)/Perioden!E6*SUMIFS(Monatsraster!$E$5:$E$100,Monatsraster!$A$5:$A$100,Perioden!$A$6,Monatsraster!$D$5:$D$100,YEAR(Perioden!$C$6)+1),2) -> 126.89
A17: Gebäudeversicherung | B17: 24,18 €/Monat × Monate | C17: =ROUND(Kosten!B14*Perioden!E6,2) -> 362.7
A18: Grundsteuer B | B18: Grundsteuer/Monat × Monate | C18: =ROUND(Kosten!B16*Perioden!E6,2) -> 235.98
A19: ="Niederschlagswasser "&YEAR(Perioden!$C$6) -> Niederschlagswasser 2024 | B19: Monatssatz × Monate des Jahres | C19: =ROUND(SUMIFS(Monatsraster!$F$5:$F$100,Monatsraster!$A$5:$A$100,Perioden!$A$6,Monatsraster!$D$5:$D$100,YEAR(Perioden!$C$6)),2) -> 66.88
A20: ="Niederschlagswasser "&(YEAR(Perioden!$C$6)+1) -> Niederschlagswasser 2025 | B20: wie oben, Folgejahr | C20: =ROUND(SUMIFS(Monatsraster!$F$5:$F$100,Monatsraster!$A$5:$A$100,Perioden!$A$6,Monatsraster!$D$5:$D$100,YEAR(Perioden!$C$6)+1),2) -> 19.88
A21: Nebenkosten netto | C21: =SUM(C11:C20) -> 3262.67
A22: Gesamtforderung (SOLL) | C22: =C21 -> 3262.67
A23: Geleistete Zahlungen (IST) | C23: =Perioden!G6 -> 2545
A24: =IF(C24>=0,"Nachzahlung (Mieter zahlt)","Guthaben (Mieter erhält)") -> Nachzahlung (Mieter zahlt) | C24: =C22-C23 -> 717.67
A26: Frist §556 Abs. 3 BGB: 30.04.2026 (bereits abgelaufen).

Sheet Abr_Leerstand
A1: Leerstandsabrechnung – von Thomas Weis zu tragen
A2: Teinacher Str. 4, 75387 Neubulach
A4: Mieter / Partei | B4: =Perioden!B7 -> Leerstand (Thomas Weis)
A5: Beginn | B5: =Perioden!C7 -> 45778
A6: Ende | B6: =Perioden!D7 -> 45869
A7: Monate | B7: =Perioden!E7 -> 3
A8: Heizschlüssel UG | B8: =Berechnung!I7 -> 0.68888328
A10: Position | B10: Berechnung | C10: Betrag
A11: WP-Strom fiktiv (Heizung) | B11: WP-kWh × Anteil 3/14 × Heizschlüssel × Strompreis | C11: =ROUND(Berechnung!C7*Perioden!J7*Berechnung!I7*Kosten!B4,2) -> 414.5
A12: Haushaltsstrom UV fiktiv | B12: UV-kWh × Anteil 3/14 × Strompreis | C12: =ROUND(Berechnung!D7*Perioden!J7*Kosten!B4,2) -> 111.78
A13: Stromgrundpreis (UG-Anteil) | B13: Monatssatz × Monate × UG-Anteil | C13: =ROUND(Perioden!K7*Kosten!B7,2) -> 45.88
A14: Gebäudeversicherung | B14: 24,18 €/Monat × Monate | C14: =ROUND(Kosten!B14*Perioden!E7,2) -> 72.54
A15: Grundsteuer B | B15: Grundsteuer/Monat × Monate | C15: =ROUND(Kosten!B16*Perioden!E7,2) -> 47.2
A16: Niederschlagswasser | B16: Monatssatz × Monate | C16: =ROUND(SUMIFS(Monatsraster!$F$5:$F$100,Monatsraster!$A$5:$A$100,Perioden!$A$7),2) -> 14.91
A17: Von Thomas zu tragen (SOLL) | C17: =SUM(C11:C16) -> 706.81

Sheet Abr_P2_Beltz
A1: Abschlussabrechnung – Fam. Beltz (Periode 2)
A2: Teinacher Str. 4, 75387 Neubulach
A4: Mieter / Partei | B4: =Perioden!B8 -> Fam. Kristin & Maximilian Beltz
A5: Beginn | B5: =Perioden!C8 -> 45870
A6: Ende | B6: =Perioden!D8 -> 46192
A7: Monate | B7: =Perioden!E8 -> 11
A8: Heizschlüssel UG | B8: =Berechnung!I8 -> 0.68888328
A10: Position | B10: Berechnung | C10: Betrag
A11: Heizkosten Wärmepumpe | B11: WP-kWh × Anteil 11/14 × Heizschlüssel × Strompreis | C11: =ROUND(Berechnung!C8*Perioden!J8*Berechnung!I8*Kosten!B4,2) -> 1519.83
A12: Warmwasser-Heizenergie | B12: Warmwasser-m³ × 20,9 kWh/m³ × Strompreis | C12: =ROUND(Berechnung!H8*Kosten!B13,2) -> 53.64
A13: Haushaltsstrom UV | B13: UV-kWh × Anteil 11/14 × Strompreis | C13: =ROUND(Berechnung!D8*Perioden!J8*Kosten!B4,2) -> 409.86
A14: Stromgrundpreis (UG-Anteil) | B14: Monatssatz × Monate × UG-Anteil | C14: =ROUND(Perioden!K8*Kosten!B7,2) -> 168.24
A15: Wasser/Abwasser | B15: (Kalt- + Warmwasser-m³ ÷ Monate) × Summe Monatstarife | C15: =ROUND((Berechnung!G8+Berechnung!H8)/Perioden!E8*SUMIFS(Monatsraster!$E$5:$E$100,Monatsraster!$A$5:$A$100,Perioden!$A$8),2) -> 385.04
A16: Gebäudeversicherung | B16: 24,18 €/Monat × Monate | C16: =ROUND(Kosten!B14*Perioden!E8,2) -> 265.98
A17: Grundsteuer B | B17: Grundsteuer/Monat × Monate | C17: =ROUND(Kosten!B16*Perioden!E8,2) -> 173.05
A18: Niederschlagswasser | B18: Monatssatz × Monate | C18: =ROUND(SUMIFS(Monatsraster!$F$5:$F$100,Monatsraster!$A$5:$A$100,Perioden!$A$8),2) -> 54.67
A19: Nebenkosten netto | C19: =SUM(C11:C18) -> 3030.31
A20: Renovierung (vereinbart) | C20: =Kosten!B18 -> 80
A21: Gesamtforderung (SOLL) | C21: =C19+C20 -> 3110.31
A22: Geleistete Zahlungen (IST) | C22: =Perioden!G8 -> 2585
A23: =IF(C23>=0,"Nachzahlung (Mieter zahlt)","Guthaben (Mieter erhält)") -> Nachzahlung (Mieter zahlt) | C23: =C21-C22 -> 525.31

Sheet Abr_Folgeperiode
A1: Abrechnung Folgeperiode – nach Eigentümerwechsel und Teilung des Wasseranschlusses
A2: Teinacher Str. 4, 75387 Neubulach
A4: Mieter / Partei | B4: =Perioden!B9 -> Neuer Eigentümer (Name folgt) – Folgeperiode
A5: Beginn | B5: =Perioden!C9 -> 46193
A6: Ende | B6: =Perioden!D9 -> 46387
A7: Monate | B7: =Perioden!E9 -> 6
A8: Heizschlüssel UG | B8: =Berechnung!I9
A10: Der Hauptwasseranschluss wurde geteilt: über Christine laufen nur noch Heizung (Wärmepumpe) und Warmwasser. Schalter: 1 = wird über Christine abgerechnet, 0 = nicht.
A11: Kaltwasser/Abwasser (eigener Anschluss → 0) | C11: 0
A12: Haushaltsstrom UV | C12: 0
A13: Stromgrundpreis (UG-Anteil) | C13: 0
A14: Gebäudeversicherung | C14: 0
A15: Grundsteuer B | C15: 0
A16: Niederschlagswasser | C16: 0
A18: Position | B18: Berechnung | C18: Betrag
A19: Heizkosten Wärmepumpe | B19: WP-kWh × Heizschlüssel × Strompreis (immer) | C19: =IF(Berechnung!C9="","",ROUND(Berechnung!C9*Perioden!J9*Berechnung!I9*Kosten!B4,2))
A20: Warmwasser-Heizenergie | B20: Warmwasser-m³ × 20,9 kWh/m³ × Strompreis (immer) | C20: =IF(Berechnung!H9="","",ROUND(Berechnung!H9*Kosten!B13,2))
A21: Wasser/Abwasser für Warmwasser-Volumen | B21: Warmwasser kommt vom Anschluss bei Christine (immer) | C21: =IF(Berechnung!H9="","",ROUND(Berechnung!H9/Perioden!E9*SUMIFS(Monatsraster!$E$5:$E$100,Monatsraster!$A$5:$A$100,Perioden!$A$9),2))
A22: Kaltwasser/Abwasser | B22: nur wenn Schalter = 1 | C22: =IF(C11=0,0,IF(Berechnung!G9="","",ROUND(Berechnung!G9/Perioden!E9*SUMIFS(Monatsraster!$E$5:$E$100,Monatsraster!$A$5:$A$100,Perioden!$A$9),2))) -> 0
A23: Haushaltsstrom UV | B23: nur wenn Schalter = 1 | C23: =IF(C12=0,0,IF(Berechnung!D9="","",ROUND(Berechnung!D9*Perioden!J9*Kosten!B4,2))) -> 0
A24: Stromgrundpreis (UG-Anteil) | B24: nur wenn Schalter = 1 | C24: =IF(C13=0,0,ROUND(Perioden!K9*Kosten!B7,2)) -> 0
A25: Gebäudeversicherung | B25: nur wenn Schalter = 1 | C25: =IF(C14=0,0,ROUND(Kosten!B14*Perioden!E9,2)) -> 0
A26: Grundsteuer B | B26: nur wenn Schalter = 1 | C26: =IF(C15=0,0,ROUND(Kosten!B16*Perioden!E9,2)) -> 0
A27: Niederschlagswasser | B27: nur wenn Schalter = 1 | C27: =IF(C16=0,0,ROUND(SUMIFS(Monatsraster!$F$5:$F$100,Monatsraster!$A$5:$A$100,Perioden!$A$9),2)) -> 0
A28: Gesamtforderung (SOLL) | C28: =IF(Berechnung!C9="","",SUM(C19:C27))
A29: Geleistete Zahlungen (IST) | C29: =Perioden!G9 -> 0
A30: =IF(C28="","",IF(C30>=0,"Nachzahlung","Guthaben")) | C30: =IF(C28="","Stand 4 fehlt",C28-C29) -> Stand 4 fehlt
A32: Annahme: Das Warmwasser-Volumen (m³) wird weiter über Christines Anschluss bezogen und daher mit dem Wasser-/Abwassertarif belastet. Bitte bestätigen.

Sheet Eigentümer
A1: Eigentümer-interne Abrechnung (Zwischenstand)
A2: Logik wie in der App. Vorläufig – siehe offene Punkte unten.
A4: Partei 1 (neuer Eigentümer) | B4: Neuer Eigentümer (Name folgt)
A5: Partei 2 | B5: Christine Weis
A7: Zahlung an Christine pro Monat – Periode 1 (€) | B7: 195
A8: Zahlung an Christine pro Monat – Periode 2 (€) – OFFEN: 195 oder 240? | B8: 195
A10: Sonderzahlungen
A11: Sonderzahlung 1 | B11: 500
A12: Sonderzahlung 2 | B12: 273
A13: Sonderzahlung 3 | B13: 210.74
A14: Sonderzahlung 4 | B14: 104
A15: Summe Sonderzahlungen | B15: =SUM(B11:B14) -> 1087.74
A16: Saldo aus früherer Abrechnung (bezahlt 03/2026) | B16: 81.99
A19: Position | B19: Betrag
A20: P1 Felix – Differenz SOLL − Vorauszahlungen | B20: =ROUND(Abr_P1_Felix!C22-Perioden!E6*B7,2) -> 337.67
A21: Leerstand – von Thomas getragen | B21: =Abr_Leerstand!C17 -> 706.81
A22: P2 Beltz – Differenz SOLL − Vorauszahlungen | B22: =ROUND(Abr_P2_Beltz!C21-Perioden!E8*B8,2) -> 965.31
A23: Zwischensumme Kosten | B23: =SUM(B20:B22) -> 2009.79
A24: Sonderzahlungen | B24: =B15 -> 1087.74
A25: Saldo aus früherer Abrechnung | B25: =B16 -> 81.99
A26: Zwischensaldo | B26: =B23+B24+B25 -> 3179.52
A28: Kulanz Warmwasser EG (von Thomas erlassen)
A29: Warmwasser EG gesamt (m³) | B29: =Zählerstände!G12-Zählerstände!E12 -> 113.547
A30: Wert (erlassen) | B30: =ROUND(B29*Kosten!B13,2) -> 584.27
A32: Folgeperiode (ab Eigentümerwechsel)
A33: Zahlung an Christine pro Monat in der Folgeperiode (€) | B33: 0
A34: SOLL Folgeperiode (Heizung + Warmwasser etc.) | B34: =Abr_Folgeperiode!C28
A35: Saldo Folgeperiode (SOLL − gezahlt) | B35: =IF(B34="","",B34-Perioden!E9*B33)
A37: Offene Punkte
A38: • Ab welchem Monat zahlt Thomas 240 €/Mon statt 195 €/Mon?
A39: • Beltz-Vorauszahlung im Zwischenstand mit 195 €/Mon angesetzt (B8).
A40: • Finale EnBW-Jahresrechnung 2025/26 zur Grundpreis-Verifizierung steht aus.
A41: • Datum der Teilung des Hauptwasseranschlusses klären – betrifft ggf. das Ende der Beltz-Periode.

Sheet Monatsraster
A1: Hilfstabelle: Monate je Periode und Tarif des jeweiligen Kalenderjahres
A2: Nur Hilfsrechnung – nichts eintragen. Verteilt Wasser- und Niederschlagskosten monatsgenau auf die Kalenderjahre.
A4: Periode | B4: Monat Nr. | C4: Monat | D4: Jahr | E4: Wassertarif €/m³ | F4: Niederschlag €/Monat
A5: =Perioden!$A$6 -> P1 | B5: 1 | C5: =IF(B5<=Perioden!$E$6,EDATE(Perioden!$C$6,B5-1),"") -> 45323 | D5: =IF(C5="","",YEAR(C5)) -> 2024 | E5: =IF(C5="",0,INDEX(Kosten!$B$21:$B$27,MATCH(D5,Kosten!$A$21:$A$27,0))) -> 7.63 | F5: =IF(C5="",0,INDEX(Kosten!$D$21:$D$27,MATCH(D5,Kosten!$A$21:$A$27,0))) -> 6.08
A6: =Perioden!$A$6 -> P1 | B6: 2 | C6: =IF(B6<=Perioden!$E$6,EDATE(Perioden!$C$6,B6-1),"") -> 45352 | D6: =IF(C6="","",YEAR(C6)) -> 2024 | E6: =IF(C6="",0,INDEX(Kosten!$B$21:$B$27,MATCH(D6,Kosten!$A$21:$A$27,0))) -> 7.63 | F6: =IF(C6="",0,INDEX(Kosten!$D$21:$D$27,MATCH(D6,Kosten!$A$21:$A$27,0))) -> 6.08
A7: =Perioden!$A$6 -> P1 | B7: 3 | C7: =IF(B7<=Perioden!$E$6,EDATE(Perioden!$C$6,B7-1),"") -> 45383 | D7: =IF(C7="","",YEAR(C7)) -> 2024 | E7: =IF(C7="",0,INDEX(Kosten!$B$21:$B$27,MATCH(D7,Kosten!$A$21:$A$27,0))) -> 7.63 | F7: =IF(C7="",0,INDEX(Kosten!$D$21:$D$27,MATCH(D7,Kosten!$A$21:$A$27,0))) -> 6.08
A8: =Perioden!$A$6 -> P1 | B8: 4 | C8: =IF(B8<=Perioden!$E$6,EDATE(Perioden!$C$6,B8-1),"") -> 45413 | D8: =IF(C8="","",YEAR(C8)) -> 2024 | E8: =IF(C8="",0,INDEX(Kosten!$B$21:$B$27,MATCH(D8,Kosten!$A$21:$A$27,0))) -> 7.63 | F8: =IF(C8="",0,INDEX(Kosten!$D$21:$D$27,MATCH(D8,Kosten!$A$21:$A$27,0))) -> 6.08
A9: =Perioden!$A$6 -> P1 | B9: 5 | C9: =IF(B9<=Perioden!$E$6,EDATE(Perioden!$C$6,B9-1),"") -> 45444 | D9: =IF(C9="","",YEAR(C9)) -> 2024 | E9: =IF(C9="",0,INDEX(Kosten!$B$21:$B$27,MATCH(D9,Kosten!$A$21:$A$27,0))) -> 7.63 | F9: =IF(C9="",0,INDEX(Kosten!$D$21:$D$27,MATCH(D9,Kosten!$A$21:$A$27,0))) -> 6.08
A10: =Perioden!$A$6 -> P1 | B10: 6 | C10: =IF(B10<=Perioden!$E$6,EDATE(Perioden!$C$6,B10-1),"") -> 45474 | D10: =IF(C10="","",YEAR(C10)) -> 2024 | E10: =IF(C10="",0,INDEX(Kosten!$B$21:$B$27,MATCH(D10,Kosten!$A$21:$A$27,0))) -> 7.63 | F10: =IF(C10="",0,INDEX(Kosten!$D$21:$D$27,MATCH(D10,Kosten!$A$21:$A$27,0))) -> 6.08
A11: =Perioden!$A$6 -> P1 | B11: 7 | C11: =IF(B11<=Perioden!$E$6,EDATE(Perioden!$C$6,B11-1),"") -> 45505 | D11: =IF(C11="","",YEAR(C11)) -> 2024 | E11: =IF(C11="",0,INDEX(Kosten!$B$21:$B$27,MATCH(D11,Kosten!$A$21:$A$27,0))) -> 7.63 | F11: =IF(C11="",0,INDEX(Kosten!$D$21:$D$27,MATCH(D11,Kosten!$A$21:$A$27,0))) -> 6.08
A12: =Perioden!$A$6 -> P1 | B12: 8 | C12: =IF(B12<=Perioden!$E$6,EDATE(Perioden!$C$6,B12-1),"") -> 45536 | D12: =IF(C12="","",YEAR(C12)) -> 2024 | E12: =IF(C12="",0,INDEX(Kosten!$B$21:$B$27,MATCH(D12,Kosten!$A$21:$A$27,0))) -> 7.63 | F12: =IF(C12="",0,INDEX(Kosten!$D$21:$D$27,MATCH(D12,Kosten!$A$21:$A$27,0))) -> 6.08
A13: =Perioden!$A$6 -> P1 | B13: 9 | C13: =IF(B13<=Perioden!$E$6,EDATE(Perioden!$C$6,B13-1),"") -> 45566 | D13: =IF(C13="","",YEAR(C13)) -> 2024 | E13: =IF(C13="",0,INDEX(Kosten!$B$21:$B$27,MATCH(D13,Kosten!$A$21:$A$27,0))) -> 7.63 | F13: =IF(C13="",0,INDEX(Kosten!$D$21:$D$27,MATCH(D13,Kosten!$A$21:$A$27,0))) -> 6.08
A14: =Perioden!$A$6 -> P1 | B14: 10 | C14: =IF(B14<=Perioden!$E$6,EDATE(Perioden!$C$6,B14-1),"") -> 45597 | D14: =IF(C14="","",YEAR(C14)) -> 2024 | E14: =IF(C14="",0,INDEX(Kosten!$B$21:$B$27,MATCH(D14,Kosten!$A$21:$A$27,0))) -> 7.63 | F14: =IF(C14="",0,INDEX(Kosten!$D$21:$D$27,MATCH(D14,Kosten!$A$21:$A$27,0))) -> 6.08
A15: =Perioden!$A$6 -> P1 | B15: 11 | C15: =IF(B15<=Perioden!$E$6,EDATE(Perioden!$C$6,B15-1),"") -> 45627 | D15: =IF(C15="","",YEAR(C15)) -> 2024 | E15: =IF(C15="",0,INDEX(Kosten!$B$21:$B$27,MATCH(D15,Kosten!$A$21:$A$27,0))) -> 7.63 | F15: =IF(C15="",0,INDEX(Kosten!$D$21:$D$27,MATCH(D15,Kosten!$A$21:$A$27,0))) -> 6.08
A16: =Perioden!$A$6 -> P1 | B16: 12 | C16: =IF(B16<=Perioden!$E$6,EDATE(Perioden!$C$6,B16-1),"") -> 45658 | D16: =IF(C16="","",YEAR(C16)) -> 2025 | E16: =IF(C16="",0,INDEX(Kosten!$B$21:$B$27,MATCH(D16,Kosten!$A$21:$A$27,0))) -> 7.44 | F16: =IF(C16="",0,INDEX(Kosten!$D$21:$D$27,MATCH(D16,Kosten!$A$21:$A$27,0))) -> 4.97
... A28: =Perioden!$A$6 -> P1 | B28: 24 | C28: =IF(B28<=Perioden!$E$6,EDATE(Perioden!$C$6,B28-1),"") | D28: =IF(C28="","",YEAR(C28)) | E28: =IF(C28="",0,INDEX(Kosten!$B$21:$B$27,MATCH(D28,Kosten!$A$21:$A$27,0))) -> 0 | F28: =IF(C28="",0,INDEX(Kosten!$D$21:$D$27,MATCH(D28,Kosten!$A$21:$A$27,0))) -> 0
A29: =Perioden!$A$7 -> LEER | B29: 1 | C29: =IF(B29<=Perioden!$E$7,EDATE(Perioden!$C$7,B29-1),"") -> 45778 | D29: =IF(C29="","",YEAR(C29)) -> 2025 | E29: =IF(C29="",0,INDEX(Kosten!$B$21:$B$27,MATCH(D29,Kosten!$A$21:$A$27,0))) -> 7.44 | F29: =IF(C29="",0,INDEX(Kosten!$D$21:$D$27,MATCH(D29,Kosten!$A$21:$A$27,0))) -> 4.97
A30: =Perioden!$A$7 -> LEER | B30: 2 | C30: =IF(B30<=Perioden!$E$7,EDATE(Perioden!$C$7,B30-1),"") -> 45809 | D30: =IF(C30="","",YEAR(C30)) -> 2025 | E30: =IF(C30="",0,INDEX(Kosten!$B$21:$B$27,MATCH(D30,Kosten!$A$21:$A$27,0))) -> 7.44 | F30: =IF(C30="",0,INDEX(Kosten!$D$21:$D$27,MATCH(D30,Kosten!$A$21:$A$27,0))) -> 4.97
A31: =Perioden!$A$7 -> LEER | B31: 3 | C31: =IF(B31<=Perioden!$E$7,EDATE(Perioden!$C$7,B31-1),"") -> 45839 | D31: =IF(C31="","",YEAR(C31)) -> 2025 | E31: =IF(C31="",0,INDEX(Kosten!$B$21:$B$27,MATCH(D31,Kosten!$A$21:$A$27,0))) -> 7.44 | F31: =IF(C31="",0,INDEX(Kosten!$D$21:$D$27,MATCH(D31,Kosten!$A$21:$A$27,0))) -> 4.97
A32: =Perioden!$A$7 -> LEER | B32: 4 | C32: =IF(B32<=Perioden!$E$7,EDATE(Perioden!$C$7,B32-1),"") | D32: =IF(C32="","",YEAR(C32)) | E32: =IF(C32="",0,INDEX(Kosten!$B$21:$B$27,MATCH(D32,Kosten!$A$21:$A$27,0))) -> 0 | F32: =IF(C32="",0,INDEX(Kosten!$D$21:$D$27,MATCH(D32,Kosten!$A$21:$A$27,0))) -> 0
A33: =Perioden!$A$7 -> LEER | B33: 5 | C33: =IF(B33<=Perioden!$E$7,EDATE(Perioden!$C$7,B33-1),"") | D33: =IF(C33="","",YEAR(C33)) | E33: =IF(C33="",0,INDEX(Kosten!$B$21:$B$27,MATCH(D33,Kosten!$A$21:$A$27,0))) -> 0 | F33: =IF(C33="",0,INDEX(Kosten!$D$21:$D$27,MATCH(D33,Kosten!$A$21:$A$27,0))) -> 0
A34: =Perioden!$A$7 -> LEER | B34: 6 | C34: =IF(B34<=Perioden!$E$7,EDATE(Perioden!$C$7,B34-1),"") | D34: =IF(C34="","",YEAR(C34)) | E34: =IF(C34="",0,INDEX(Kosten!$B$21:$B$27,MATCH(D34,Kosten!$A$21:$A$27,0))) -> 0 | F34: =IF(C34="",0,INDEX(Kosten!$D$21:$D$27,MATCH(D34,Kosten!$A$21:$A$27,0))) -> 0
A35: =Perioden!$A$7 -> LEER | B35: 7 | C35: =IF(B35<=Perioden!$E$7,EDATE(Perioden!$C$7,B35-1),"") | D35: =IF(C35="","",YEAR(C35)) | E35: =IF(C35="",0,INDEX(Kosten!$B$21:$B$27,MATCH(D35,Kosten!$A$21:$A$27,0))) -> 0 | F35: =IF(C35="",0,INDEX(Kosten!$D$21:$D$27,MATCH(D35,Kosten!$A$21:$A$27,0))) -> 0
A36: =Perioden!$A$7 -> LEER | B36: 8 | C36: =IF(B36<=Perioden!$E$7,EDATE(Perioden!$C$7,B36-1),"") | D36: =IF(C36="","",YEAR(C36)) | E36: =IF(C36="",0,INDEX(Kosten!$B$21:$B$27,MATCH(D36,Kosten!$A$21:$A$27,0))) -> 0 | F36: =IF(C36="",0,INDEX(Kosten!$D$21:$D$27,MATCH(D36,Kosten!$A$21:$A$27,0))) -> 0
A37: =Perioden!$A$7 -> LEER | B37: 9 | C37: =IF(B37<=Perioden!$E$7,EDATE(Perioden!$C$7,B37-1),"") | D37: =IF(C37="","",YEAR(C37)) | E37: =IF(C37="",0,INDEX(Kosten!$B$21:$B$27,MATCH(D37,Kosten!$A$21:$A$27,0))) -> 0 | F37: =IF(C37="",0,INDEX(Kosten!$D$21:$D$27,MATCH(D37,Kosten!$A$21:$A$27,0))) -> 0
A38: =Perioden!$A$7 -> LEER | B38: 10 | C38: =IF(B38<=Perioden!$E$7,EDATE(Perioden!$C$7,B38-1),"") | D38: =IF(C38="","",YEAR(C38)) | E38: =IF(C38="",0,INDEX(Kosten!$B$21:$B$27,MATCH(D38,Kosten!$A$21:$A$27,0))) -> 0 | F38: =IF(C38="",0,INDEX(Kosten!$D$21:$D$27,MATCH(D38,Kosten!$A$21:$A$27,0))) -> 0
A39: =Perioden!$A$7 -> LEER | B39: 11 | C39: =IF(B39<=Perioden!$E$7,EDATE(Perioden!$C$7,B39-1),"") | D39: =IF(C39="","",YEAR(C39)) | E39: =IF(C39="",0,INDEX(Kosten!$B$21:$B$27,MATCH(D39,Kosten!$A$21:$A$27,0))) -> 0 | F39: =IF(C39="",0,INDEX(Kosten!$D$21:$D$27,MATCH(D39,Kosten!$A$21:$A$27,0))) -> 0
A40: =Perioden!$A$7 -> LEER | B40: 12 | C40: =IF(B40<=Perioden!$E$7,EDATE(Perioden!$C$7,B40-1),"") | D40: =IF(C40="","",YEAR(C40)) | E40: =IF(C40="",0,INDEX(Kosten!$B$21:$B$27,MATCH(D40,Kosten!$A$21:$A$27,0))) -> 0 | F40: =IF(C40="",0,INDEX(Kosten!$D$21:$D$27,MATCH(D40,Kosten!$A$21:$A$27,0))) -> 0
... A52: =Perioden!$A$7 -> LEER | B52: 24 | C52: =IF(B52<=Perioden!$E$7,EDATE(Perioden!$C$7,B52-1),"") | D52: =IF(C52="","",YEAR(C52)) | E52: =IF(C52="",0,INDEX(Kosten!$B$21:$B$27,MATCH(D52,Kosten!$A$21:$A$27,0))) -> 0 | F52: =IF(C52="",0,INDEX(Kosten!$D$21:$D$27,MATCH(D52,Kosten!$A$21:$A$27,0))) -> 0
A53: =Perioden!$A$8 -> P2 | B53: 1 | C53: =IF(B53<=Perioden!$E$8,EDATE(Perioden!$C$8,B53-1),"") -> 45870 | D53: =IF(C53="","",YEAR(C53)) -> 2025 | E53: =IF(C53="",0,INDEX(Kosten!$B$21:$B$27,MATCH(D53,Kosten!$A$21:$A$27,0))) -> 7.44 | F53: =IF(C53="",0,INDEX(Kosten!$D$21:$D$27,MATCH(D53,Kosten!$A$21:$A$27,0))) -> 4.97
A54: =Perioden!$A$8 -> P2 | B54: 2 | C54: =IF(B54<=Perioden!$E$8,EDATE(Perioden!$C$8,B54-1),"") -> 45901 | D54: =IF(C54="","",YEAR(C54)) -> 2025 | E54: =IF(C54="",0,INDEX(Kosten!$B$21:$B$27,MATCH(D54,Kosten!$A$21:$A$27,0))) -> 7.44 | F54: =IF(C54="",0,INDEX(Kosten!$D$21:$D$27,MATCH(D54,Kosten!$A$21:$A$27,0))) -> 4.97
A55: =Perioden!$A$8 -> P2 | B55: 3 | C55: =IF(B55<=Perioden!$E$8,EDATE(Perioden!$C$8,B55-1),"") -> 45931 | D55: =IF(C55="","",YEAR(C55)) -> 2025 | E55: =IF(C55="",0,INDEX(Kosten!$B$21:$B$27,MATCH(D55,Kosten!$A$21:$A$27,0))) -> 7.44 | F55: =IF(C55="",0,INDEX(Kosten!$D$21:$D$27,MATCH(D55,Kosten!$A$21:$A$27,0))) -> 4.97
A56: =Perioden!$A$8 -> P2 | B56: 4 | C56: =IF(B56<=Perioden!$E$8,EDATE(Perioden!$C$8,B56-1),"") -> 45962 | D56: =IF(C56="","",YEAR(C56)) -> 2025 | E56: =IF(C56="",0,INDEX(Kosten!$B$21:$B$27,MATCH(D56,Kosten!$A$21:$A$27,0))) -> 7.44 | F56: =IF(C56="",0,INDEX(Kosten!$D$21:$D$27,MATCH(D56,Kosten!$A$21:$A$27,0))) -> 4.97
A57: =Perioden!$A$8 -> P2 | B57: 5 | C57: =IF(B57<=Perioden!$E$8,EDATE(Perioden!$C$8,B57-1),"") -> 45992 | D57: =IF(C57="","",YEAR(C57)) -> 2025 | E57: =IF(C57="",0,INDEX(Kosten!$B$21:$B$27,MATCH(D57,Kosten!$A$21:$A$27,0))) -> 7.44 | F57: =IF(C57="",0,INDEX(Kosten!$D$21:$D$27,MATCH(D57,Kosten!$A$21:$A$27,0))) -> 4.97
A58: =Perioden!$A$8 -> P2 | B58: 6 | C58: =IF(B58<=Perioden!$E$8,EDATE(Perioden!$C$8,B58-1),"") -> 46023 | D58: =IF(C58="","",YEAR(C58)) -> 2026 | E58: =IF(C58="",0,INDEX(Kosten!$B$21:$B$27,MATCH(D58,Kosten!$A$21:$A$27,0))) -> 7.44 | F58: =IF(C58="",0,INDEX(Kosten!$D$21:$D$27,MATCH(D58,Kosten!$A$21:$A$27,0))) -> 4.97
A59: =Perioden!$A$8 -> P2 | B59: 7 | C59: =IF(B59<=Perioden!$E$8,EDATE(Perioden!$C$8,B59-1),"") -> 46054 | D59: =IF(C59="","",YEAR(C59)) -> 2026 | E59: =IF(C59="",0,INDEX(Kosten!$B$21:$B$27,MATCH(D59,Kosten!$A$21:$A$27,0))) -> 7.44 | F59: =IF(C59="",0,INDEX(Kosten!$D$21:$D$27,MATCH(D59,Kosten!$A$21:$A$27,0))) -> 4.97
A60: =Perioden!$A$8 -> P2 | B60: 8 | C60: =IF(B60<=Perioden!$E$8,EDATE(Perioden!$C$8,B60-1),"") -> 46082 | D60: =IF(C60="","",YEAR(C60)) -> 2026 | E60: =IF(C60="",0,INDEX(Kosten!$B$21:$B$27,MATCH(D60,Kosten!$A$21:$A$27,0))) -> 7.44 | F60: =IF(C60="",0,INDEX(Kosten!$D$21:$D$27,MATCH(D60,Kosten!$A$21:$A$27,0))) -> 4.97
A61: =Perioden!$A$8 -> P2 | B61: 9 | C61: =IF(B61<=Perioden!$E$8,EDATE(Perioden!$C$8,B61-1),"") -> 46113 | D61: =IF(C61="","",YEAR(C61)) -> 2026 | E61: =IF(C61="",0,INDEX(Kosten!$B$21:$B$27,MATCH(D61,Kosten!$A$21:$A$27,0))) -> 7.44 | F61: =IF(C61="",0,INDEX(Kosten!$D$21:$D$27,MATCH(D61,Kosten!$A$21:$A$27,0))) -> 4.97
A62: =Perioden!$A$8 -> P2 | B62: 10 | C62: =IF(B62<=Perioden!$E$8,EDATE(Perioden!$C$8,B62-1),"") -> 46143 | D62: =IF(C62="","",YEAR(C62)) -> 2026 | E62: =IF(C62="",0,INDEX(Kosten!$B$21:$B$27,MATCH(D62,Kosten!$A$21:$A$27,0))) -> 7.44 | F62: =IF(C62="",0,INDEX(Kosten!$D$21:$D$27,MATCH(D62,Kosten!$A$21:$A$27,0))) -> 4.97
A63: =Perioden!$A$8 -> P2 | B63: 11 | C63: =IF(B63<=Perioden!$E$8,EDATE(Perioden!$C$8,B63-1),"") -> 46174 | D63: =IF(C63="","",YEAR(C63)) -> 2026 | E63: =IF(C63="",0,INDEX(Kosten!$B$21:$B$27,MATCH(D63,Kosten!$A$21:$A$27,0))) -> 7.44 | F63: =IF(C63="",0,INDEX(Kosten!$D$21:$D$27,MATCH(D63,Kosten!$A$21:$A$27,0))) -> 4.97
...
